Workbook
Name WebWps_Form: 成品日检表报表!$A$1:$J$295
Name WebWps_Form_RhS4ZQP58FdX24OE: 成品日检表!$A$1:$K$465

Sheet 成品日检表报表
A1: 填写ID | B1: 时间 | C1: 检验:组别 | D1: 检验:加工单号 | E1: 检验:检验数量 | F1: 检验:抽检数 | G1: 检验:不良数 | H1: 检验:不良项目 | I1: 检验:判定 | J1: 签名:图片

Sheet 成品日检表
A1: 填写ID | B1: 时间 | C1: 检验:组别 | D1: 检验:加工单号 | E1: 检验:检验数量 | F1: 检验:抽检数 | G1: 检验:不良数 | H1: 检验:不良项目 | I1: 检验:判定 | J1: 签名:图片 | K1: 反馈单:图片_1

Sheet 数据分析表
A1: 本日日期 | B1: =TODAY() | E1: 周别 | F1: =WEEKNUM(B1,2) | L1: 开始日期（含） | M1: 结束日期（含）
A2: =IF(AND(YEAR(L2)=YEAR(M2),MONTH(L2)=MONTH(M2)),MONTH(L2),"区间") | B2: 月出货抽检不良统计表 | E2: =$A$2 | F2: 月各组返工批次统计 | H2: =$A$2 | I2: 月检验数据表 | L2: 46023 | M2: 46053
A3: 项 目 | B3: 不良批次 | C3: 排名 | E3: 组别 | F3: 返工批次 | H3: 检验数量 | I3: 抽检数 | J3: 不良数 | K3: 不良率
A4: 端子包角不良 | B4: =COUNTIFS('成品日检表'!$B$2:$B$2,">="&$L$2,'成品日检表'!$B$2:$B$2,"<"&($M$2+1),'成品日检表'!$H$2:$H$2,"*a*") | C4: =RANK(B4,$B$4:$B$27,0) | E4: U1 | F4: =COUNTIFS('成品日检表'!$B$2:$B$2,">="&$L$2,'成品日检表'!$B$2:$B$2,"<"&($M$2+1),'成品日检表'!$C$2:$C$2,E4,'成品日检表'!$I$2:$I$2,"返工") | H4: =SUMIFS('成品日检表'!$E$2:$E$2,'成品日检表'!$B$2:$B$2,">="&$L$2,'成品日检表'!$B$2:$B$2,"<"&($M$2+1)) | I4: =SUMIFS('成品日检表'!$F$2:$F$2,'成品日检表'!$B$2:$B$2,">="&$L$2,'成品日检表'!$B$2:$B$2,"<"&($M$2+1)) | J4: =SUMIFS('成品日检表'!$G$2:$G$2,'成品日检表'!$B$2:$B$2,">="&$L$2,'成品日检表'!$B$2:$B$2,"<"&($M$2+1)) | K4: =IFERROR(J4/I4,0)
A5: 走线槽漏扎带 | B5: =COUNTIFS('成品日检表'!$B$2:$B$2,">="&$L$2,'成品日检表'!$B$2:$B$2,"<"&($M$2+1),'成品日检表'!$H$2:$H$2,"*b*") | C5: =RANK(B5,$B$4:$B$27,0) | E5: U2 | F5: =COUNTIFS('成品日检表'!$B$2:$B$2,">="&$L$2,'成品日检表'!$B$2:$B$2,"<"&($M$2+1),'成品日检表'!$C$2:$C$2,E5,'成品日检表'!$I$2:$I$2,"返工")
A6: 漏锁片 | B6: =COUNTIFS('成品日检表'!$B$2:$B$2,">="&$L$2,'成品日检表'!$B$2:$B$2,"<"&($M$2+1),'成品日检表'!$H$2:$H$2,"*c*") | C6: =RANK(B6,$B$4:$B$27,0) | E6: U3 | F6: =COUNTIFS('成品日检表'!$B$2:$B$2,">="&$L$2,'成品日检表'!$B$2:$B$2,"<"&($M$2+1),'成品日检表'!$C$2:$C$2,E6,'成品日检表'!$I$2:$I$2,"返工")
A7: 漏扣卡扣 | B7: =COUNTIFS('成品日检表'!$B$2:$B$2,">="&$L$2,'成品日检表'!$B$2:$B$2,"<"&($M$2+1),'成品日检表'!$H$2:$H$2,"*d*") | C7: =RANK(B7,$B$4:$B$27,0) | E7: U4 | F7: =COUNTIFS('成品日检表'!$B$2:$B$2,">="&$L$2,'成品日检表'!$B$2:$B$2,"<"&($M$2+1),'成品日检表'!$C$2:$C$2,E7,'成品日检表'!$I$2:$I$2,"返工")
A8: 漏剪扎带 | B8: =COUNTIFS('成品日检表'!$B$2:$B$2,">="&$L$2,'成品日检表'!$B$2:$B$2,"<"&($M$2+1),'成品日检表'!$H$2:$H$2,"*e*") | C8: =RANK(B8,$B$4:$B$27,0) | E8: U5 | F8: =COUNTIFS('成品日检表'!$B$2:$B$2,">="&$L$2,'成品日检表'!$B$2:$B$2,"<"&($M$2+1),'成品日检表'!$C$2:$C$2,E8,'成品日检表'!$I$2:$I$2,"返工")
A9: 插入不足 | B9: =COUNTIFS('成品日检表'!$B$2:$B$2,">="&$L$2,'成品日检表'!$B$2:$B$2,"<"&($M$2+1),'成品日检表'!$H$2:$H$2,"*f*") | C9: =RANK(B9,$B$4:$B$27,0) | E9: U6 | F9: =COUNTIFS('成品日检表'!$B$2:$B$2,">="&$L$2,'成品日检表'!$B$2:$B$2,"<"&($M$2+1),'成品日检表'!$C$2:$C$2,E9,'成品日检表'!$I$2:$I$2,"返工")
A10: 漏胶 | B10: =COUNTIFS('成品日检表'!$B$2:$B$2,">="&$L$2,'成品日检表'!$B$2:$B$2,"<"&($M$2+1),'成品日检表'!$H$2:$H$2,"*g*") | C10: =RANK(B10,$B$4:$B$27,0) | E10: U7 | F10: =COUNTIFS('成品日检表'!$B$2:$B$2,">="&$L$2,'成品日检表'!$B$2:$B$2,"<"&($M$2+1),'成品日检表'!$C$2:$C$2,E10,'成品日检表'!$I$2:$I$2,"返工")
A11: 组付漏扎带 | B11: =COUNTIFS('成品日检表'!$B$2:$B$2,">="&$L$2,'成品日检表'!$B$2:$B$2,"<"&($M$2+1),'成品日检表'!$H$2:$H$2,"*h*") | C11: =RANK(B11,$B$4:$B$27,0) | E11: U8 | F11: =COUNTIFS('成品日检表'!$B$2:$B$2,">="&$L$2,'成品日检表'!$B$2:$B$2,"<"&($M$2+1),'成品日检表'!$C$2:$C$2,E11,'成品日检表'!$I$2:$I$2,"返工")
A12: 漏海绵 | B12: =COUNTIFS('成品日检表'!$B$2:$B$2,">="&$L$2,'成品日检表'!$B$2:$B$2,"<"&($M$2+1),'成品日检表'!$H$2:$H$2,"*i*") | C12: =RANK(B12,$B$4:$B$27,0) | E12: 合计 | F12: =SUM(F4:F11)
A13: 组付尺寸不良 | B13: =COUNTIFS('成品日检表'!$B$2:$B$2,">="&$L$2,'成品日检表'!$B$2:$B$2,"<"&($M$2+1),'成品日检表'!$H$2:$H$2,"*j*") | C13: =RANK(B13,$B$4:$B$27,0)
A14: 走线槽尺寸不良 | B14: =COUNTIFS('成品日检表'!$B$2:$B$2,">="&$L$2,'成品日检表'!$B$2:$B$2,"<"&($M$2+1),'成品日检表'!$H$2:$H$2,"*k*") | C14: =RANK(B14,$B$4:$B$27,0)
A15: 热缩管不良 | B15: =COUNTIFS('成品日检表'!$B$2:$B$2,">="&$L$2,'成品日检表'!$B$2:$B$2,"<"&($M$2+1),'成品日检表'!$H$2:$H$2,"*l*") | C15: =RANK(B15,$B$4:$B$27,0)
A16: 端子反插 | B16: =COUNTIFS('成品日检表'!$B$2:$B$2,">="&$L$2,'成品日检表'!$B$2:$B$2,"<"&($M$2+1),'成品日检表'!$H$2:$H$2,"*m*") | C16: =RANK(B16,$B$4:$B$27,0)
A17: 端子变形 | B17: =COUNTIFS('成品日检表'!$B$2:$B$2,">="&$L$2,'成品日检表'!$B$2:$B$2,"<"&($M$2+1),'成品日检表'!$H$2:$H$2,"*n*") | C17: =RANK(B17,$B$4:$B$27,0)
A18: 漏装塑壳 | B18: =COUNTIFS('成品日检表'!$B$2:$B$2,">="&$L$2,'成品日检表'!$B$2:$B$2,"<"&($M$2+1),'成品日检表'!$H$2:$H$2,"*o*") | C18: =RANK(B18,$B$4:$B$27,0)
A19: 标签贴错 | B19: =COUNTIFS('成品日检表'!$B$2:$B$2,">="&$L$2,'成品日检表'!$B$2:$B$2,"<"&($M$2+1),'成品日检表'!$H$2:$H$2,"*p*") | C19: =RANK(B19,$B$4:$B$27,0)
A20: 塑壳用错（国产与进口混用或用相似塑壳） | B20: =COUNTIFS('成品日检表'!$B$2:$B$2,">="&$L$2,'成品日检表'!$B$2:$B$2,"<"&($M$2+1),'成品日检表'!$H$2:$H$2,"*q*") | C20: =RANK(B20,$B$4:$B$27,0)
A21: 护套用错 | B21: =COUNTIFS('成品日检表'!$B$2:$B$2,">="&$L$2,'成品日检表'!$B$2:$B$2,"<"&($M$2+1),'成品日检表'!$H$2:$H$2,"*r*") | C21: =RANK(B21,$B$4:$B$27,0)
A22: 扎带松 | B22: =COUNTIFS('成品日检表'!$B$2:$B$2,">="&$L$2,'成品日检表'!$B$2:$B$2,"<"&($M$2+1),'成品日检表'!$H$2:$H$2,"*s*") | C22: =RANK(B22,$B$4:$B$27,0)
A23: 线剪断 | B23: =COUNTIFS('成品日检表'!$B$2:$B$2,">="&$L$2,'成品日检表'!$B$2:$B$2,"<"&($M$2+1),'成品日检表'!$H$2:$H$2,"*t*") | C23: =RANK(B23,$B$4:$B$27,0)
A24: 防水塞未装到位 | B24: =COUNTIFS('成品日检表'!$B$2:$B$2,">="&$L$2,'成品日检表'!$B$2:$B$2,"<"&($M$2+1),'成品日检表'!$H$2:$H$2,"*u*") | C24: =RANK(B24,$B$4:$B$27,0)
A25: 塑壳坏 | B25: =COUNTIFS('成品日检表'!$B$2:$B$2,">="&$L$2,'成品日检表'!$B$2:$B$2,"<"&($M$2+1),'成品日检表'!$H$2:$H$2,"*v*") | C25: =RANK(B25,$B$4:$B$27,0)
A26: 端子浅压 | B26: =COUNTIFS('成品日检表'!$B$2:$B$2,">="&$L$2,'成品日检表'!$B$2:$B$2,"<"&($M$2+1),'成品日检表'!$H$2:$H$2,"*w*") | C26: =RANK(B26,$B$4:$B$27,0)
A27: 端子深压 | B27: =COUNTIFS('成品日检表'!$B$2:$B$2,">="&$L$2,'成品日检表'!$B$2:$B$2,"<"&($M$2+1),'成品日检表'!$H$2:$H$2,"*x*") | C27: =RANK(B27,$B$4:$B$27,0)
A28: 合计 | B28: =SUM(B4:B27)
A30: 本日日期 | B30: =TODAY() | E30: 周别 | F30: =WEEKNUM(B30,2)
L31: 周开始（含） | M31: 周结束（含）
A32: =WEEKNUM(L32,21) | B32: 周出货抽检不良统计表 | E32: =$A$32 | F32: 周各组返工批次统计 | H32: =$A$32 | I32: 周检验数据表 | L32: 46048 | M32: 46054
A33: 项 目 | B33: 不良批次 | C33: 排名 | E33: 组别 | F33: 返工批次 | H33: 检验数量 | I33: 抽检数 | J33: 不良数 | K33: 不良率
A34: 端子包角不良 | B34: =COUNTIFS('成品日检表'!$B$2:$B$2,">="&$L$32,'成品日检表'!$B$2:$B$2,"<"&($M$32+1),'成品日检表'!$H$2:$H$2,"*a*") | C34: =RANK(B34,$B$34:$B$57,0) | E34: U1 | F34: =COUNTIFS('成品日检表'!$B$2:$B$2,">="&$L$32,'成品日检表'!$B$2:$B$2,"<"&($M$32+1),'成品日检表'!$C$2:$C$2,E34,'成品日检表'!$I$2:$I$2,"返工") | H34: =SUMIFS('成品日检表'!$E$2:$E$2,'成品日检表'!$B$2:$B$2,">="&$L$32,'成品日检表'!$B$2:$B$2,"<"&($M$32+1)) | I34: =SUMIFS('成品日检表'!$F$2:$F$2,'成品日检表'!$B$2:$B$2,">="&$L$32,'成品日检表'!$B$2:$B$2,"<"&($M$32+1)) | J34: =SUMIFS('成品日检表'!$G$2:$G$2,'成品日检表'!$B$2:$B$2,">="&$L$32,'成品日检表'!$B$2:$B$2,"<"&($M$32+1)) | K34: =IFERROR(J34/I34,0)
A35: 走线槽漏扎带 | B35: =COUNTIFS('成品日检表'!$B$2:$B$2,">="&$L$32,'成品日检表'!$B$2:$B$2,"<"&($M$32+1),'成品日检表'!$H$2:$H$2,"*b*") | C35: =RANK(B35,$B$34:$B$57,0) | E35: U2 | F35: =COUNTIFS('成品日检表'!$B$2:$B$2,">="&$L$32,'成品日检表'!$B$2:$B$2,"<"&($M$32+1),'成品日检表'!$C$2:$C$2,E35,'成品日检表'!$I$2:$I$2,"返工")
A36: 漏锁片 | B36: =COUNTIFS('成品日检表'!$B$2:$B$2,">="&$L$32,'成品日检表'!$B$2:$B$2,"<"&($M$32+1),'成品日检表'!$H$2:$H$2,"*c*") | C36: =RANK(B36,$B$34:$B$57,0) | E36: U3 | F36: =COUNTIFS('成品日检表'!$B$2:$B$2,">="&$L$32,'成品日检表'!$B$2:$B$2,"<"&($M$32+1),'成品日检表'!$C$2:$C$2,E36,'成品日检表'!$I$2:$I$2,"返工")
A37: 漏扣卡扣 | B37: =COUNTIFS('成品日检表'!$B$2:$B$2,">="&$L$32,'成品日检表'!$B$2:$B$2,"<"&($M$32+1),'成品日检表'!$H$2:$H$2,"*d*") | C37: =RANK(B37,$B$34:$B$57,0) | E37: U4 | F37: =COUNTIFS('成品日检表'!$B$2:$B$2,">="&$L$32,'成品日检表'!$B$2:$B$2,"<"&($M$32+1),'成品日检表'!$C$2:$C$2,E37,'成品日检表'!$I$2:$I$2,"返工")
A38: 漏剪扎带 | B38: =COUNTIFS('成品日检表'!$B$2:$B$2,">="&$L$32,'成品日检表'!$B$2:$B$2,"<"&($M$32+1),'成品日检表'!$H$2:$H$2,"*e*") | C38: =RANK(B38,$B$34:$B$57,0) | E38: U5 | F38: =COUNTIFS('成品日检表'!$B$2:$B$2,">="&$L$32,'成品日检表'!$B$2:$B$2,"<"&($M$32+1),'成品日检表'!$C$2:$C$2,E38,'成品日检表'!$I$2:$I$2,"返工")
A39: 插入不足 | B39: =COUNTIFS('成品日检表'!$B$2:$B$2,">="&$L$32,'成品日检表'!$B$2:$B$2,"<"&($M$32+1),'成品日检表'!$H$2:$H$2,"*f*") | C39: =RANK(B39,$B$34:$B$57,0) | E39: U6 | F39: =COUNTIFS('成品日检表'!$B$2:$B$2,">="&$L$32,'成品日检表'!$B$2:$B$2,"<"&($M$32+1),'成品日检表'!$C$2:$C$2,E39,'成品日检表'!$I$2:$I$2,"返工")
A40: 漏胶 | B40: =COUNTIFS('成品日检表'!$B$2:$B$2,">="&$L$32,'成品日检表'!$B$2:$B$2,"<"&($M$32+1),'成品日检表'!$H$2:$H$2,"*g*") | C40: =RANK(B40,$B$34:$B$57,0) | E40: U7 | F40: =COUNTIFS('成品日检表'!$B$2:$B$2,">="&$L$32,'成品日检表'!$B$2:$B$2,"<"&($M$32+1),'成品日检表'!$C$2:$C$2,E40,'成品日检表'!$I$2:$I$2,"返工")
A41: 组付漏扎带 | B41: =COUNTIFS('成品日检表'!$B$2:$B$2,">="&$L$32,'成品日检表'!$B$2:$B$2,"<"&($M$32+1),'成品日检表'!$H$2:$H$2,"*h*") | C41: =RANK(B41,$B$34:$B$57,0) | E41: U8 | F41: =COUNTIFS('成品日检表'!$B$2:$B$2,">="&$L$32,'成品日检表'!$B$2:$B$2,"<"&($M$32+1),'成品日检表'!$C$2:$C$2,E41,'成品日检表'!$I$2:$I$2,"返工")
...

Sheet 工具
A2: 1 | B2: 端子包角不良
A3: 2 | B3: 走线槽漏扎带
A4: 3 | B4: 漏锁片
A5: 4 | B5: 漏扣卡扣
A6: 5 | B6: 漏剪扎带
A7: 6 | B7: 插入不足
A8: 7 | B8: 漏胶
A9: 8 | B9: 组付漏扎带
A10: 9 | B10: 漏海绵
A11: 10 | B11: 组付尺寸不良
A12: 11 | B12: 走线槽尺寸不良
A13: 12 | B13: 热缩管不良
... A25: 24 | B25: 端子深压
